Some weights of BertForSequenceClassification were not initialized from the model checkpoint at bert-base-multilingual-cased and are newly initialized: ['classifier.bias', 'classifier.weight']
You should probably TRAIN this model on a down-stream task to be able to use it for predictions and inference.
  0%|          | 0/3 [00:00<?, ?it/s]Traceback (most recent call last):
  File "C:\Users\media\programowanie\MafAI-1.0 Classic\MafAI - Open ChatBot.py", line 74, in <module>
    fine_tune_model()
  File "C:\Users\media\programowanie\MafAI-1.0 Classic\MafAI - Open ChatBot.py", line 71, in fine_tune_model
    trainer.train()
  File "C:\Users\media\AppData\Local\Programs\Python\Python310\lib\site-packages\transformers\trainer.py", line 1932, in train
    return inner_training_loop(
  File "C:\Users\media\AppData\Local\Programs\Python\Python310\lib\site-packages\transformers\trainer.py", line 2268, in _inner_training_loop
    tr_loss_step = self.training_step(model, inputs)
  File "C:\Users\media\AppData\Local\Programs\Python\Python310\lib\site-packages\transformers\trainer.py", line 3307, in training_step
    loss = self.compute_loss(model, inputs)
  File "C:\Users\media\AppData\Local\Programs\Python\Python310\lib\site-packages\transformers\trainer.py", line 3338, in compute_loss
    outputs = model(**inputs)
  File "C:\Users\media\AppData\Local\Programs\Python\Python310\lib\site-packages\torch\nn\modules\module.py", line 1532, in _wrapped_call_impl
    return self._call_impl(*args, **kwargs)
  File "C:\Users\media\AppData\Local\Programs\Python\Python310\lib\site-packages\torch\nn\modules\module.py", line 1541, in _call_impl
    return forward_call(*args, **kwargs)
  File "C:\Users\media\AppData\Local\Programs\Python\Python310\lib\site-packages\transformers\models\bert\modeling_bert.py", line 1730, in forward
    loss = loss_fct(logits.view(-1, self.num_labels), labels.view(-1))
  File "C:\Users\media\AppData\Local\Programs\Python\Python310\lib\site-packages\torch\nn\modules\module.py", line 1532, in _wrapped_call_impl
    return self._call_impl(*args, **kwargs)
  File "C:\Users\media\AppData\Local\Programs\Python\Python310\lib\site-packages\torch\nn\modules\module.py", line 1541, in _call_impl
    return forward_call(*args, **kwargs)
  File "C:\Users\media\AppData\Local\Programs\Python\Python310\lib\site-packages\torch\nn\modules\loss.py", line 1185, in forward
    return F.cross_entropy(input, target, weight=self.weight,
  File "C:\Users\media\AppData\Local\Programs\Python\Python310\lib\site-packages\torch\nn\functional.py", line 3086, in cross_entropy
    return torch._C._nn.cross_entropy_loss(input, target, weight, _Reduction.get_enum(reduction), ignore_index, label_smoothing)
ValueError: Expected input batch_size (4) to match target batch_size (512).
  0%|          | 0/3 [00:07<?, ?it/s]
